Workbook

Sheet Ohje
A2: Taloyhtiö-manager – kulu- ja elinkaariterminaali
A4: Tälle on rakennettu kaksi välilehteä alkuun: Kulut (A) ja Rakennusosat (B). Molemmat on kuvattu tarkemmin alla.
A6: VÄLILEHTI: Kulut
A7: Vastaa kysymykseen “mihin raha menee”. Rivit ovat tilinpäätöksen hoitokuluryhmät sellaisenaan (ei omaa luokittelua) täydennettynä kahdella tägillä: Luonne (Hoito/Korjaus) ja Ohjattavuus (Kiinteä/Muuttuva/Sekä). Toteumat 2023–2025 tulevat toimintakertomuksista, budjetit 2025 ja 2026 isännöitsijän talousarvioista.
A9: VÄLILEHTI: Rakennusosat
A10: Vastaa kysymykseen “milloin vastiketta pitää nostaa”. Yksi rivi = yksi rakennusosa. 'Käyttöikä min/max' on lähteestä (hallituksen selvitys tai yleinen KH-tyyppinen ohjearvo), ja sarakkeet F–G laskevat arvioidun seuraavan toimenpidevuoden automaattisesti (viimeisin toimenpide + käyttöikä). Tällä ei vielä ole kuntoarvioita, joten kaikki rivit nojaavat asennusvuoteen + taulukkokäyttöikään – se on normaali ja odotettu tilanne, ei puute.
A12: Värikoodit
A13: Sininen teksti = alkuperäisestä dokumentista poimittu luku (et muokkaa ellei lähde muutu)
A14: Musta teksti = kaava (laskee itse, älä kirjoita päälle)
A15: Keltainen tausta = arvio/oletus jota kannattaa tarkentaa (esim. kuntoarviolla)
A16: Oranssi tausta = DATA GAP: lähdedokumentissa ei ollut tätä tarkkaa tietoa, käytetty yleistä arviota
A18: Lähteet
... A37: Yleinen tulevien remonttien malli. Kustannusmatriisiin kirjoitetaan jokaiselle riville remontin kustannus oikean vuoden kohdalle, ja Skenaario-tägi (Varma/Perus/Paha) ohjaa rivin oikeaan kolmesta kassaprojektiosta. Projektio näyttää saldon kehityksen ja liputtaa ensimmäisen vuoden jolloin kassa alittaa puskurirajan – eli milloin vastiketta viimeistään pitää nostaa kussakin skenaariossa. Lämminvesivaraajat kytkeytyvät automaattisesti (linkkirivit) Pitkä aikaväli -välilehden A/B/C-laskelmasta.

Sheet Kulut
A1: Kulut – mihin raha menee
A2: Lähde: toimintakertomukset ja talousarviovertailut, tilikaudet 2023–2025
A4: Ryhmä | B4: Luonne | C4: Ohjattavuus | D4: Toteuma 2023 | E4: Toteuma 2024 | F4: Toteuma 2025 | G4: Budjetti 2025 | H4: Budjetti 2026 | I4: Poikkeama 2025 (Budj.-Tot.) | J4: Muutos 24→25 | K4: Huom. | L4: Budjetti 2024 | M4: Budjetti 2023
A5: Henkilöstökulut (hallituspalkkiot) | B5: Hoito | C5: Kiinteä | D5: 360 | E5: 600 | F5: 600 | G5: 600 | H5: 600 | I5: =G5-F5 -> 0 | J5: =IFERROR((F5-E5)/E5,"") -> 0 | L5: 360 | M5: 480
A6: Hallintopalvelut | B6: Hoito | C6: Kiinteä | D6: 8003.7 | E6: 7885.63 | F6: 7360.76 | G6: 7719.32 | H6: 7972.32 | I6: =G6-F6 -> 358.56 | J6: =IFERROR((F6-E6)/E6,"") -> -0.066560313 | K6: Isännöinti, kokouspalkkiot, pankki- ja toimistokulut | L6: 7015 | M6: 7243.96
A7: Käyttö- ja huoltopalvelut | B7: Hoito | C7: Sekä | D7: 1975.41 | E7: 1450.42 | F7: 4624.34 | G7: 1332 | H7: 3232 | I7: =G7-F7 -> -3292.34 | J7: =IFERROR((F7-E7)/E7,"") -> 2.1882765 | K7: 2025: sis. mm. palovaroittimien asennus, keinun kunnostus | L7: 1324 | M7: 1916.66
A8: Ulkoalueiden hoitopalvelut | B8: Hoito | C8: Kiinteä | D8: 3784.22 | E8: 2186.5 | F8: 2193.69 | G8: 4000 | H8: 2300 | I8: =G8-F8 -> 1806.31 | J8: =IFERROR((F8-E8)/E8,"") -> 0.0032883604 | L8: 4000 | M8: 3300
A9: Vesi- ja jätevesi | B9: Hoito | C9: Muuttuva | D9: 4995.73 | E9: 6784.9 | F9: 7067.26 | G9: 7270 | H9: 7270 | I9: =G9-F9 -> 202.74 | J9: =IFERROR((F9-E9)/E9,"") -> 0.041615941 | K9: Kulutus nousussa 3v putkeen (l/hlö/vrk) – seurattava | L9: 5270 | M9: 5240
A10: Sähkö | B10: Hoito | C10: Muuttuva | D10: 3070.51 | E10: 2624.14 | F10: 2552.01 | G10: 2860 | H10: 2750 | I10: =G10-F10 -> 307.99 | J10: =IFERROR((F10-E10)/E10,"") -> -0.027487101 | L10: 2250 | M10: 2600
A11: Jätehuolto | B11: Hoito | C11: Kiinteä | D11: 3041.94 | E11: 2873.98 | F11: 2939.55 | G11: 3000 | H11: 3000 | I11: =G11-F11 -> 60.45 | J11: =IFERROR((F11-E11)/E11,"") -> 0.022815051 | L11: 3200 | M11: 3300
A12: Vahinkovakuutukset | B12: Hoito | C12: Kiinteä | D12: 2809.46 | E12: 2147.96 | F12: 1878.41 | G12: 1874.39 | H12: 1909.33 | I12: =G12-F12 -> -4.02 | J12: =IFERROR((F12-E12)/E12,"") -> -0.12549116 | L12: 2916 | M12: 2630.11
A13: Kiinteistövero | B13: Hoito | C13: Kiinteä | D13: 4845.6 | E13: 4859.13 | F13: 4813.44 | G13: 4880 | H13: 4756.44 | I13: =G13-F13 -> 66.56 | J13: =IFERROR((F13-E13)/E13,"") -> -0.0094029178 | L13: 4859 | M13: 4845.6
A14: Korjaukset | B14: Korjaus | C14: Muuttuva | D14: 1385.06 | E14: 5348.53 | F14: 3881.55 | G14: 9400 | H14: 9680 | I14: =G14-F14 -> 5518.45 | J14: =IFERROR((F14-E14)/E14,"") -> -0.27427723 | K14: Budjetoitu ~9,5–9,7 t€ 2v putkeen, toteuma alle – kysy hallitukselta mikä korjaus on kyseessä | L14: 8000 | M14: 3000
A15: YHTEENSÄ | D15: =SUM(D5:D14) -> 34271.63 | E15: =SUM(E5:E14) -> 36761.19 | F15: =SUM(F5:F14) -> 37911.01 | G15: =SUM(G5:G14) -> 42935.71 | H15: =SUM(H5:H14) -> 43470.09 | I15: =G15-F15 -> 5024.7 | J15: =IFERROR((F15-E15)/E15,"") -> 0.031278095 | L15: =SUM(L5:L14) -> 39194 | M15: =SUM(M5:M14) -> 34556.33
A18: Yhteenveto: Luonne (2025 toteuma)
A19: Hoito yhteensä | B19: =SUMIF(B5:B14,"Hoito",F5:F14) -> 34029.46 | C19: =IFERROR(B19/F15,"") -> 0.89761418
A20: Korjaus yhteensä | B20: =SUMIF(B5:B14,"Korjaus",F5:F14) -> 3881.55 | C20: =IFERROR(B20/F15,"") -> 0.10238582
A22: Yhteenveto: Ohjattavuus (2025 toteuma)
A23: Kiinteä yhteensä | B23: =SUMIF(C5:C14,"Kiinteä",F5:F14) -> 19785.85 | C23: =IFERROR(B23/F15,"") -> 0.52190248
A24: Muuttuva yhteensä | B24: =SUMIF(C5:C14,"Muuttuva",F5:F14) -> 13500.82 | C24: =IFERROR(B24/F15,"") -> 0.35611871
A25: Sekä yhteensä | B25: =SUMIF(C5:C14,"Sekä",F5:F14) -> 4624.34 | C25: =IFERROR(B25/F15,"") -> 0.12197881

Sheet Rakennusosat
A1: Rakennusosat – elinkaariaikajana
A2: Talo: rivitalo, puuelementti, valmistunut 2007. Lähde: hallituksen kirjallinen selvitys kunnossapito- ja muutostyöistä (2024) + toimintakertomukset.
A4: Rakennusosa | B4: Viimeisin toimenpide (v) | C4: Toimenpiteen tyyppi | D4: Käyttöikä min (v) | E4: Käyttöikä max (v) | F4: Arvio: aikaisin- taan (v) | G4: Arvio: viimeis- taan (v) | H4: Lähde | I4: Tietolähteen taso | J4: Huom. | K4: Arvioitu hinta | L4: Rivityyppi
A5: Piha-asfaltti | B5: 2012 | C5: Uusiminen | D5: 20 | E5: 20 | F5: =B5+D5 -> 2032 | G5: =B5+E5 -> 2032 | H5: Hallituksen selvitys 2024, s.15 | I5: Asennusvuosi + taulukko | L5: Kerta
A6: Parvekkeiden alapintojen käsittely | B6: 2015 | C6: Pintakäsittely | D6: 10 | E6: 15 | F6: =B6+D6 -> 2025 | G6: =B6+E6 -> 2030 | H6: Hallituksen selvitys 2024, s.15 (yleisarvio, ei oma sykli) | I6: Karkea haarukka | J6: DATA GAP: tarkkaa pintakäsittelyväliä ei ole kirjattu, arvioitu yleisen käytännön mukaan | L6: Kerta
A7: Ilmastointihormit ja -koneet, huolto | B7: 2016 | C7: Määräaikaishuolto | D7: 5 | E7: 10 | F7: =B7+D7 -> 2021 | G7: =B7+E7 -> 2026 | H7: Hallituksen selvitys 2024, s.15 (ei omaa sykliä) | I7: Karkea haarukka | J7: DATA GAP: huoltosykli ei ole taulukossa, tavanomainen IV-huoltoväli oletettu | L7: Kerta
A8: Viemärilinjat ja kaivot, tarkastus | B8: 2018 | C8: Tarkastus | D8: 5 | E8: 10 | F8: =B8+D8 -> 2023 | G8: =B8+E8 -> 2028 | H8: Hallituksen selvitys 2024, s.15 (ei omaa sykliä) | I8: Karkea haarukka | J8: DATA GAP: tarkastussykli oletettu | L8: Kerta
A9: Ulkoseinien maalaus | B9: 2019 | C9: Pintakäsittely | D9: 10 | E9: 15 | F9: =B9+D9 -> 2029 | G9: =B9+E9 -> 2034 | H9: Hallituksen selvitys 2024, s.15 (puuverhous 30–50v = rakenteen ikä, ei maalausväli) | I9: Karkea haarukka | J9: DATA GAP: maalausväli arvioitu, ei virallinen lähde | L9: Kerta
A10: Vesikate, huolto | B10: 2021 | C10: Kevyt huolto | D10: 5 | E10: 10 | F10: =B10+D10 -> 2026 | G10: =B10+E10 -> 2031 | H10: Hallituksen selvitys 2024, s.15 (ei omaa sykliä) | I10: Karkea haarukka | J10: Kate harja/tiili – taulukossa vain peltikatteille omat arvot | L10: Kerta
A11: Palovaroittimet | B11: 2025 | C11: Uusiminen | D11: 10 | E11: 10 | F11: =B11+D11 -> 2035 | G11: =B11+E11 -> 2035 | H11: Hallituksen selvitys 2024, s.15 | I11: Asennusvuosi + taulukko | L11: Kerta
A12: Käyttövesiputket | B12: 2007 | C12: Alkuperäinen | D12: 25 | E12: 50 | F12: =B12+D12 -> 2032 | G12: =B12+E12 -> 2057 | H12: Hallituksen selvitys 2024, s.15 | I12: Asennusvuosi + taulukko | J12: Iso hajonta – kuntoarvio kaventaisi merkittävästi | L12: Kerta
A13: Lämminvesivaraajat | B13: 2007 | C13: Alkuperäinen | D13: 15 | E13: 25 | F13: =B13+D13 -> 2022 | G13: =B13+E13 -> 2032 | H13: DATA GAP – ei omaa riviä Hallituksen selvitys 2024 s.15 -taulukossa, yleinen ohjearvo sähkövaraajille | I13: Karkea haarukka | J13: Mainittu hallituksen kunnossapitotarveselvityksessä 2024–2028 (“varautuminen vaihtoon”) – arvioitu ikkuna on jo alkanut, kannattaa selvittää nykykunto pian | K13: 1 800 €/kpl (ks. Pitkä aikaväli -välilehti) | L13: Jatkuva (poistuma)
A14: Salaojajärjestelmä | B14: 2007 | C14: Alkuperäinen | D14: 30 | E14: 50 | F14: =B14+D14 -> 2037 | G14: =B14+E14 -> 2057 | H14: Hallituksen selvitys 2024, s.15 | I14: Asennusvuosi + taulukko | L14: Kerta
A15: Julkisivu, puuverhousrakenne | B15: 2007 | C15: Alkuperäinen | D15: 30 | E15: 50 | F15: =B15+D15 -> 2037 | G15: =B15+E15 -> 2057 | H15: Hallituksen selvitys 2024, s.15 | I15: Asennusvuosi + taulukko | J15: Pintakäsittely (eri rivi) tehtävä tämän välissä useammin | L15: Kerta
A16: Perustukset | B16: 2007 | C16: Alkuperäinen | D16: 50 | E16: 60 | F16: =B16+D16 -> 2057 | G16: =B16+E16 -> 2067 | H16: Hallituksen selvitys 2024, s.15 | I16: Asennusvuosi + taulukko | J16: Ei kiireellinen | L16: Kerta
A17: Vesikate, täysi uusiminen | B17: 2007 | C17: Alkuperäinen | D17: 40 | E17: 60 | F17: =B17+D17 -> 2047 | G17: =B17+E17 -> 2067 | H17: DATA GAP – ei omaa riviä taulukossa tiilikatteelle | I17: Karkea haarukka | J17: Taulukossa vain peltikatteille – vahvista kuntoarviolla ennen isoja päätöksiä | L17: Kerta
A20: Hinta-arviot puuttuvat vielä useimmilta riveiltä (oranssi = DATA GAP) – täydennä kun urakkatarjous tai kuntoarvio saadaan. Lämminvesivaraajien skenaariolaskelma on omalla välilehdellään (Pitkä aikaväli), koska se ei ole yksi remonttivuosi vaan jatkuva poistuma.

Sheet Kuluva kausi 2026
A1: Kuluva kausi 2026
A2: Budjetti ja käytettävissä oleva raha tälle tilikaudelle, sekä suunnitellut ja toteutuneet korjaukset. Lisää rivejä kumpaankin tauluun tarvittaessa – kaavat laajenevat mukaan riville 30 asti.
A4: TILANNE NYT
A5: Kassa (31.12.2025) | B5: ='Taloudellinen asema'!C14 -> 22208.49
A6: 2026 korjausvaraus (budjetti) | B6: =Kulut!H14 -> 9680
A8: SUUNNITELLUT KORJAUKSET 2026
A9: Kohde / toimenpide | B9: Arvioitu hinta | C9: Ajankohta | D9: Tila | E9: Huom.
A10: Ilmanvaihdon puhdistus | C10: 2026 | D10: Suunniteltu | E10: Hallituksen kunnossapitotarveselvitys 2024–2028
A19: SUUNNITELTU YHTEENSÄ | B19: =SUM(B10:B18) -> 0
A22: TOTEUTUNEET KORJAUKSET 2026
A23: Kohde / toimenpide | B23: Hinta | C23: Pvm | D23: Lähde/tosite | E23: Huom.
A34: TOTEUTUNUT YHTEENSÄ | B34: =SUM(B24:B33) -> 0
A37: YHTEENVETO
A38: Varauksesta käytetty (toteutunut) | B38: =B34 -> 0
A39: Varauksesta vielä sidottu (suunniteltu, ei toteutunut) | B39: =B19 -> 0
A40: Varauksesta vapaana | B40: =B6-B34-B39 -> 9680
A41: Mahtuuko budjettiin? | B41: =IF(B40>=0,"Kyllä","EI – ylittää") -> Kyllä

Sheet Pitkä aikaväli
A1: Pitkä aikaväli – lämminvesivaraajien poistumaskenaariot
A2: 13 asuntoa, 13 alkuperäistä varaajaa (2007), 1 jo vaihdettu – 12 jäljellä. Yksikköhinta 1 800 € on karkea arvio (et muistanut tarkkaa summaa), tärkeä tarkentaa kun seuraava vaihto tehdään.
A4: Yksikköhinta / varaaja | B4: 1800
A5: Jäljellä (kpl) | B5: 12
A7: POISTUMASKENAARIOT (kpl/vuosi)
A8: Vuosi | B8: A: Hidas (kpl) | C8: A: kust. | D8: B: Perusura (kpl) | E8: B: kust. | F8: C: Ryväs (kpl) | G8: C: kust.
A9: 2026 | B9: 0 | C9: =B9*$B$4 -> 0 | D9: 1 | E9: =D9*$B$4 -> 1800 | F9: 0 | G9: =F9*$B$4 -> 0
A10: 2027 | B10: 1 | C10: =B10*$B$4 -> 1800 | D10: 1 | E10: =D10*$B$4 -> 1800 | F10: 0 | G10: =F10*$B$4 -> 0
A11: 2028 | B11: 0 | C11: =B11*$B$4 -> 0 | D11: 1 | E11: =D11*$B$4 -> 1800 | F11: 5 | G11: =F11*$B$4 -> 9000
A12: 2029 | B12: 0 | C12: =B12*$B$4 -> 0 | D12: 2 | E12: =D12*$B$4 -> 3600 | F12: 2 | G12: =F12*$B$4 -> 3600
A13: 2030 | B13: 1 | C13: =B13*$B$4 -> 1800 | D13: 2 | E13: =D13*$B$4 -> 3600 | F13: 2 | G13: =F13*$B$4 -> 3600
A14: 2031 | B14: 0 | C14: =B14*$B$4 -> 0 | D14: 2 | E14: =D14*$B$4 -> 3600 | F14: 2 | G14: =F14*$B$4 -> 3600
A15: 2032 | B15: 0 | C15: =B15*$B$4 -> 0 | D15: 1 | E15: =D15*$B$4 -> 1800 | F15: 1 | G15: =F15*$B$4 -> 1800
A16: 2033 | B16: 1 | C16: =B16*$B$4 -> 1800 | D16: 1 | E16: =D16*$B$4 -> 1800 | F16: 0 | G16: =F16*$B$4 -> 0
A17: 2034 | B17: 0 | C17: =B17*$B$4 -> 0 | D17: 1 | E17: =D17*$B$4 -> 1800 | F17: 0 | G17: =F17*$B$4 -> 0
A18: 2035 | B18: 0 | C18: =B18*$B$4 -> 0 | D18: 0 | E18: =D18*$B$4 -> 0 | F18: 0 | G18: =F18*$B$4 -> 0
A19: 2036 | B19: 1 | C19: =B19*$B$4 -> 1800 | D19: 0 | E19: =D19*$B$4 -> 0 | F19: 0 | G19: =F19*$B$4 -> 0
A20: 2037 | B20: 0 | C20: =B20*$B$4 -> 0 | D20: 0 | E20: =D20*$B$4 -> 0 | F20: 0 | G20: =F20*$B$4 -> 0
... A23: 2040 | B23: 0 | C23: =B23*$B$4 -> 0 | D23: 0 | E23: =D23*$B$4 -> 0 | F23: 0 | G23: =F23*$B$4 -> 0
A24: Yhteensä (kpl / €) | B24: =SUM(B9:B23) -> 5 | C24: =SUM(C9:C23) -> 9000 | D24: =SUM(D9:D23) -> 12 | E24: =SUM(E9:E23) -> 21600 | F24: =SUM(F9:F23) -> 12 | G24: =SUM(G9:G23) -> 21600
A25: Huipputilikausi (€) | C25: =MAX(C9:C23) -> 1800 | E25: =MAX(E9:E23) -> 3600 | G25: =MAX(G9:G23) -> 9000
A27: A = havaittu tahti jatkuu (1 kpl / n. 3 v). B = ikääntyvä kanta hajoaa kiihtyvästi, kaikki vaihdettu n. 2034 mennessä. C = stressitesti: sama asennusvuosi + sama vesi voi tarkoittaa useamman hajoavan yhtä aikaa. Tämä on mallinnus, ei ennuste – tarkoitus on nähdä kuinka iso puskuri kannattaa pitää varalla.
A29: STRATEGIAVERTAILU
A30: Strategia | B30: Yksikköhinta | C30: Kokonaishinta | D30: Ajoitus | E30: Huom.
A31: Nykyinen: vaihto rikkoutuessa | B31: =B4 -> 1800 | C31: =12*B4 -> 21600 | D31: Hajautettu, ks. skenaariot | E31: Ei suunnittelukustannusta, mutta päivystysluonteinen ja vesivahinkoriski jos varaaja hajoaa ilman ennakkovaroitusta
A32: Vaihtoehto: suunniteltu sarjavaihto | B32: =B4*0.85 -> 1530 | C32: =12*B4*0.85 -> 18360 | D32: Kertaurakka, 1 tilikausi | E32: Oletettu n. 15 % sarja-alennus (arvio, ei tarjousta) – mutta osa varaajista vaihdettaisiin ennen käyttöikänsä loppua, ja koko summa yhtenä vuonna kuormittaa kassaa/vastiketta kerralla
A34: Tämänhetkinen näyttö (vain 1/13 hajonnut 19 vuodessa) tukee ennemmin nykyistä vaihda-rikkoutuessa-tapaa kuin kallista ennakoivaa sarjavaihtoa – mutta tätä kannattaa arvioida uudelleen jos vikatahti kiihtyy (esim. 2–3 hajoaa peräkkäisinä vuosina).

Sheet Skenaariot
A1: Skenaariot – tulevien remonttien kassavaikutus
A2: Kirjoita jokaiselle riville remontin kustannus sille vuodelle jolloin sen odotetaan osuvan. Kertaremontti = yksi luku; jakautuva = useampi; jatkuva = luku joka vuodelle. Skenaario-sarake ohjaa rivin oikeaan kassaprojektioon. Lisää rivejä tyhjien jatkoksi – kaavat kattavat kaikki rivit taulukon loppuun asti.
A4: Oletukset (muokattavat, keltaiset)
A5: Lähtökassa (2025 lopun kassa) | C5: ='Taloudellinen asema'!C14 -> 22208.49
A6: Korjauksiin käytettävissä / vuosi | C6: 9680
A7: Puskuriraja (hälytys jos saldo alittaa) | C7: 10000
A9: Skenaario-tägit
A10: Varma | B10: tulee joka tapauksessa
A11: Perus | B11: todennäköinen lisä
A12: Paha | B12: stressitesti / riski
A14: KUSTANNUSMATRIISI (€ per vuosi)
A15: Kohde / toimenpide | B15: Skenaario | C15: Huom. | D15: 2026 | E15: 2027 | F15: 2028 | G15: 2029 | H15: 2030 | I15: 2031 | J15: 2032 | K15: 2033 | L15: 2034 | M15: 2035 | N15: 2036 | O15: 2037 | P15: 2038 | Q15: 2039 | R15: 2040 | S15: 2041 | T15: 2042 | U15: 2043 | V15: 2044 | W15: 2045
A16: Lämminvesivaraajat (hidas) | B16: Varma | C16: Linkki: Pitkä aikaväli A-skenaario | D16: ='Pitkä aikaväli'!C9 -> 0 | E16: ='Pitkä aikaväli'!C10 -> 1800 | F16: ='Pitkä aikaväli'!C11 -> 0 | G16: ='Pitkä aikaväli'!C12 -> 0 | H16: ='Pitkä aikaväli'!C13 -> 1800 | I16: ='Pitkä aikaväli'!C14 -> 0 | J16: ='Pitkä aikaväli'!C15 -> 0 | K16: ='Pitkä aikaväli'!C16 -> 1800 | L16: ='Pitkä aikaväli'!C17 -> 0 | M16: ='Pitkä aikaväli'!C18 -> 0 | N16: ='Pitkä aikaväli'!C19 -> 1800 | O16: ='Pitkä aikaväli'!C20 -> 0 | P16: ='Pitkä aikaväli'!C21 -> 0 | Q16: ='Pitkä aikaväli'!C22 -> 1800 | R16: ='Pitkä aikaväli'!C23 -> 0
A17: Lämminvesivaraajat (perusuran lisä) | B17: Perus | C17: Linkki: B miinus A | D17: ='Pitkä aikaväli'!E9-'Pitkä aikaväli'!C9 -> 1800 | E17: ='Pitkä aikaväli'!E10-'Pitkä aikaväli'!C10 -> 0 | F17: ='Pitkä aikaväli'!E11-'Pitkä aikaväli'!C11 -> 1800 | G17: ='Pitkä aikaväli'!E12-'Pitkä aikaväli'!C12 -> 3600 | H17: ='Pitkä aikaväli'!E13-'Pitkä aikaväli'!C13 -> 1800 | I17: ='Pitkä aikaväli'!E14-'Pitkä aikaväli'!C14 -> 3600 | J17: ='Pitkä aikaväli'!E15-'Pitkä aikaväli'!C15 -> 1800 | K17: ='Pitkä aikaväli'!E16-'Pitkä aikaväli'!C16 -> 0 | L17: ='Pitkä aikaväli'!E17-'Pitkä aikaväli'!C17 -> 1800 | M17: ='Pitkä aikaväli'!E18-'Pitkä aikaväli'!C18 -> 0 | N17: ='Pitkä aikaväli'!E19-'Pitkä aikaväli'!C19 -> -1800 | O17: ='Pitkä aikaväli'!E20-'Pitkä aikaväli'!C20 -> 0 | P17: ='Pitkä aikaväli'!E21-'Pitkä aikaväli'!C21 -> 0 | Q17: ='Pitkä aikaväli'!E22-'Pitkä aikaväli'!C22 -> -1800 | R17: ='Pitkä aikaväli'!E23-'Pitkä aikaväli'!C23 -> 0
A18: Lämminvesivaraajat (ryvään lisä) | B18: Paha | C18: Linkki: C miinus B | D18: ='Pitkä aikaväli'!G9-'Pitkä aikaväli'!E9 -> -1800 | E18: ='Pitkä aikaväli'!G10-'Pitkä aikaväli'!E10 -> -1800 | F18: ='Pitkä aikaväli'!G11-'Pitkä aikaväli'!E11 -> 7200 | G18: ='Pitkä aikaväli'!G12-'Pitkä aikaväli'!E12 -> 0 | H18: ='Pitkä aikaväli'!G13-'Pitkä aikaväli'!E13 -> 0 | I18: ='Pitkä aikaväli'!G14-'Pitkä aikaväli'!E14 -> 0 | J18: ='Pitkä aikaväli'!G15-'Pitkä aikaväli'!E15 -> 0 | K18: ='Pitkä aikaväli'!G16-'Pitkä aikaväli'!E16 -> -1800 | L18: ='Pitkä aikaväli'!G17-'Pitkä aikaväli'!E17 -> -1800 | M18: ='Pitkä aikaväli'!G18-'Pitkä aikaväli'!E18 -> 0 | N18: ='Pitkä aikaväli'!G19-'Pitkä aikaväli'!E19 -> 0 | O18: ='Pitkä aikaväli'!G20-'Pitkä aikaväli'!E20 -> 0 | P18: ='Pitkä aikaväli'!G21-'Pitkä aikaväli'!E21 -> 0 | Q18: ='Pitkä aikaväli'!G22-'Pitkä aikaväli'!E22 -> 0 | R18: ='Pitkä aikaväli'!G23-'Pitkä aikaväli'!E23 -> 0
A19: IV-putkien eristys + homekorjaus (1 asunto) | B19: Varma | C19: Toteutunut, 2 600 € / asunto | D19: 2600
A20: Homekorjaus, todenn. jatko (2 asuntoa) | B20: Perus | C20: 2 x 2 600 €, arvioitu 2027–2028 | E20: 2600 | F20: 2600
A21: Homekorjaus, paha skenaario (3. asunto + laajenema) | B21: Paha | C21: 3 x 2 600 € worst case; tässä 3. asunto + varaus laajenemalle | E21: 2600 | G21: 2600
A35: VUOSIKULUT SKENAARIOITTAIN
A36: Optimistinen (vain Varma) | D36: =SUMIF($B$16:$B$33,"Varma",D$16:D$33) -> 2600 | E36: =SUMIF($B$16:$B$33,"Varma",E$16:E$33) -> 1800 | F36: =SUMIF($B$16:$B$33,"Varma",F$16:F$33) -> 0 | G36: =SUMIF($B$16:$B$33,"Varma",G$16:G$33) -> 0 | H36: =SUMIF($B$16:$B$33,"Varma",H$16:H$33) -> 1800 | I36: =SUMIF($B$16:$B$33,"Varma",I$16:I$33) -> 0 | J36: =SUMIF($B$16:$B$33,"Varma",J$16:J$33) -> 0 | K36: =SUMIF($B$16:$B$33,"Varma",K$16:K$33) -> 1800 | ... W36: =SUMIF($B$16:$B$33,"Varma",W$16:W$33) -> 0
A37: Perusura (Varma + Perus) | D37: =SUMIF($B$16:$B$33,"Varma",D$16:D$33)+SUMIF($B$16:$B$33,"Perus",D$16:D$33) -> 4400 | E37: =SUMIF($B$16:$B$33,"Varma",E$16:E$33)+SUMIF($B$16:$B$33,"Perus",E$16:E$33) -> 4400 | F37: =SUMIF($B$16:$B$33,"Varma",F$16:F$33)+SUMIF($B$16:$B$33,"Perus",F$16:F$33) -> 4400 | G37: =SUMIF($B$16:$B$33,"Varma",G$16:G$33)+SUMIF($B$16:$B$33,"Perus",G$16:G$33) -> 3600 | H37: =SUMIF($B$16:$B$33,"Varma",H$16:H$33)+SUMIF($B$16:$B$33,"Perus",H$16:H$33) -> 3600 | I37: =SUMIF($B$16:$B$33,"Varma",I$16:I$33)+SUMIF($B$16:$B$33,"Perus",I$16:I$33) -> 3600 | J37: =SUMIF($B$16:$B$33,"Varma",J$16:J$33)+SUMIF($B$16:$B$33,"Perus",J$16:J$33) -> 1800 | K37: =SUMIF($B$16:$B$33,"Varma",K$16:K$33)+SUMIF($B$16:$B$33,"Perus",K$16:K$33) -> 1800 | ... W37: =SUMIF($B$16:$B$33,"Varma",W$16:W$33)+SUMIF($B$16:$B$33,"Perus",W$16:W$33) -> 0
A38: Pessimistinen (kaikki) | D38: =SUM(D$16:D$33) -> 2600 | E38: =SUM(E$16:E$33) -> 5200 | F38: =SUM(F$16:F$33) -> 11600 | G38: =SUM(G$16:G$33) -> 6200 | H38: =SUM(H$16:H$33) -> 3600 | I38: =SUM(I$16:I$33) -> 3600 | J38: =SUM(J$16:J$33) -> 1800 | K38: =SUM(K$16:K$33) -> 0 | ... W38: =SUM(W$16:W$33) -> 0
A40: KASSAPROJEKTIO (saldo vuoden lopussa)
A41: Saldo – Optimistinen | D41: =C5+C6-D36 -> 29288.49 | E41: =D41+C6-E36 -> 37168.49 | F41: =E41+C6-F36 -> 46848.49 | G41: =F41+C6-G36 -> 56528.49 | H41: =G41+C6-H36 -> 64408.49 | I41: =H41+C6-I36 -> 74088.49 | J41: =I41+C6-J36 -> 83768.49 | K41: =J41+C6-K36 -> 91648.49 | L41: =K41+C6-L36 -> 101328.49 | M41: =L41+C6-M36 -> 111008.49 | N41: =M41+C6-N36 -> 118888.49 | O41: =N41+C6-O36 -> 128568.49 | P41: =O41+C6-P36 -> 138248.49 | Q41: =P41+C6-Q36 -> 146128.49 | R41: =Q41+C6-R36 -> 155808.49 | S41: =R41+C6-S36 -> 165488.49 | T41: =S41+C6-T36 -> 175168.49 | U41: =T41+C6-U36 -> 184848.49 | V41: =U41+C6-V36 -> 194528.49 | W41: =V41+C6-W36 -> 204208.49
A42: Saldo – Perusura | D42: =C5+C6-D37 -> 27488.49 | E42: =D42+C6-E37 -> 32768.49 | F42: =E42+C6-F37 -> 38048.49 | G42: =F42+C6-G37 -> 44128.49 | H42: =G42+C6-H37 -> 50208.49 | I42: =H42+C6-I37 -> 56288.49 | J42: =I42+C6-J37 -> 64168.49 | K42: =J42+C6-K37 -> 72048.49 | L42: =K42+C6-L37 -> 79928.49 | M42: =L42+C6-M37 -> 89608.49 | N42: =M42+C6-N37 -> 99288.49 | O42: =N42+C6-O37 -> 108968.49 | P42: =O42+C6-P37 -> 118648.49 | Q42: =P42+C6-Q37 -> 128328.49 | R42: =Q42+C6-R37 -> 138008.49 | S42: =R42+C6-S37 -> 147688.49 | T42: =S42+C6-T37 -> 157368.49 | U42: =T42+C6-U37 -> 167048.49 | V42: =U42+C6-V37 -> 176728.49 | W42: =V42+C6-W37 -> 186408.49
A43: Saldo – Pessimistinen | D43: =C5+C6-D38 -> 29288.49 | E43: =D43+C6-E38 -> 33768.49 | F43: =E43+C6-F38 -> 31848.49 | G43: =F43+C6-G38 -> 35328.49 | H43: =G43+C6-H38 -> 41408.49 | I43: =H43+C6-I38 -> 47488.49 | J43: =I43+C6-J38 -> 55368.49 | K43: =J43+C6-K38 -> 65048.49 | L43: =K43+C6-L38 -> 74728.49 | M43: =L43+C6-M38 -> 84408.49 | N43: =M43+C6-N38 -> 94088.49 | O43: =N43+C6-O38 -> 103768.49 | P43: =O43+C6-P38 -> 113448.49 | Q43: =P43+C6-Q38 -> 123128.49 | R43: =Q43+C6-R38 -> 132808.49 | S43: =R43+C6-S38 -> 142488.49 | T43: =S43+C6-T38 -> 152168.49 | U43: =T43+C6-U38 -> 161848.49 | V43: =U43+C6-V38 -> 171528.49 | W43: =V43+C6-W38 -> 181208.49
A45: HÄLYTYS: 1. vuosi jolloin saldo alittaa puskurirajan
A46: Optimistinen: | C46: {=IFERROR(INDEX(D$15:W$15,MATCH(TRUE(),D41:W41<C7,0)),"Ei näköpiirissä (2026–2045)")} -> Ei näköpiirissä (2026–2045)
A47: Perusura: | C47: {=IFERROR(INDEX(D$15:W$15,MATCH(TRUE(),D42:W42<C7,0)),"Ei näköpiirissä (2026–2045)")} -> Ei näköpiirissä (2026–2045)
A48: Pessimistinen: | C48: {=IFERROR(INDEX(D$15:W$15,MATCH(TRUE(),D43:W43<C7,0)),"Ei näköpiirissä (2026–2045)")} -> Ei näköpiirissä (2026–2045)
A50: Kun säädät keltaista “Korjauksiin käytettävissä / vuosi” -solua ylöspäin, näet paljonko vuosivarausta pitäisi nostaa jotta pessimistinen skenaario pysyy puskurirajan yläpuolella – se on suoraan arvio vastikkeen korotustarpeesta.
A52: Nykyisillä luvuilla kassa kasvaa kaikissa skenaarioissa eikä puskuriraja ylity – vuosivaraus (9 680 €) riittää näihin remontteihin. Hälytys laukeaa vasta jos lisäät matriisiin isompia remontteja (esim. julkisivu, katto, putkisto hinta-arvioineen) tai lasket vuosivarausta. Juuri niiden isojen remonttien lisääminen on tämän välilehden varsinainen käyttötarkoitus.

Sheet Kulut tileittäin
A1: Kulut tileittäin – tilikohtainen erittely
A2: Lähde: Tuloslaskelma tileittäin 2025/2024 + talousarvio 2026 + 2023 toimintakertomuksen tekstiosa (Korjaukset täysin katettu, muualla osittain – ks. alaviite).
A4: Tili | B4: Nimi | C4: Toteuma 2023 | D4: Toteuma 2024 | E4: Toteuma 2025 | F4: Budjetti 2026 | G4: Huom.
A5: HENKILÖSTÖKULUT
A6: 5060 | B6: Hallituksen palkkiot | C6: -360 | D6: -600 | E6: -600 | F6: -600
B7: Henkilöstökulut yhteensä | C7: =SUM(C6) -> -360 | D7: =SUM(D6) -> -600 | E7: =SUM(E6) -> -600 | F7: =SUM(F6) -> -600
A9: HALLINTOPALVELUT
A10: 5300 | B10: Isännöintipalkkiot | D10: -5298.76 | E10: -5521.32 | F10: -5701.32
A11: 5301 | B11: Isänn.kokouspalkkiot | D11: -979 | E11: -720 | F11: -850
A12: 5310 | B12: Isännöinnin erill. korv. | D12: -154 | E12: -112.5 | F12: -180
A13: 5370 | B13: Toimistokulut | D13: -418.2 | E13: -232.16 | F13: -400
A14: 5373 | B14: Postikulut | D14: -3.38 | E14: -5.97
A15: 5375 | B15: Jäsenmaksut | D15: -218 | E15: -218 | F15: -226
A16: 5377 | B16: Pankkikulut | D16: -464.29 | E16: -500.81 | F16: -560
A17: 5383 | B17: Julkiset maksut | D17: -350 | E17: -50 | F17: -55
B18: Hallintopalvelut yhteensä | C18: =-Kulut!D6 -> -8003.7 | D18: =SUM(D10:D17) -> -7885.63 | E18: =SUM(E10:E17) -> -7360.76 | F18: =SUM(F10:F17) -> -7972.32
A20: KÄYTTÖ- JA HUOLTOPALVELUT
A21: 5440 | B21: Laajakaistamaksut | D21: -695.24 | E21: -700.44 | F21: -700.44
A22: 5441 | B22: Kaapeli-tv-maksut | D22: -624 | E22: -631.56 | F22: -631.56
A23: 5480 | B23: Muut huollon kulut | C23: -646.66 | D23: -131.18 | E23: -3292.34 | F23: -1900 | G23: 2023: mm. viemäreiden huuhtelua. 2025: palovaroittimet, keinun kunnostus, kourujen puhdistus
B24: Käyttö- ja huoltopalvelut yhteensä | C24: =-Kulut!D7 -> -1975.41 | D24: =SUM(D21:D23) -> -1450.42 | E24: =SUM(E21:E23) -> -4624.34 | F24: =SUM(F21:F23) -> -3232
A26: ULKOALUEIDEN HOITOPALVELUT
A27: 5530 | B27: Ulkoalueiden kiinteistönhuolto | C27: -3748.32 | D27: -2157.6 | E27: -2183.7 | F27: -2300 | G27: 2023: sis. pensasaitojen leikkaus
A28: 5550 | B28: Ulkoalueiden tarveaineet | E28: -9.99
A29: 5560 | B29: Ulkoalueiden työkalut | D29: -28.9
B30: Ulkoalueiden hoitopalvelut yhteensä | C30: =-Kulut!D8 -> -3784.22 | D30: =SUM(D27:D29) -> -2186.5 | E30: =SUM(E27:E29) -> -2193.69 | F30: =SUM(F27:F29) -> -2300
A32: VESI- JA JÄTEVESI
A33: 5800 | B33: Vesi- ja jätevesimaksut | D33: -6514.9 | E33: -6797.26 | F33: -7000
A34: 5850 | B34: Hulevesimaksut | D34: -270 | E34: -270 | F34: -270
B35: Vesi- ja jätevesi yhteensä | C35: =-Kulut!D9 -> -4995.73 | D35: =SUM(D33:D34) -> -6784.9 | E35: =SUM(E33:E34) -> -7067.26 | F35: =SUM(F33:F34) -> -7270
A37: SÄHKÖ
A38: 5910 | B38: Sähkön siirto | D38: -1795.67 | E38: -1832.8 | F38: -1900
A39: 5920 | B39: Sähkön myynti | D39: -828.47 | E39: -719.21 | F39: -850
B40: Sähkö yhteensä | C40: =-Kulut!D10 -> -3070.51 | D40: =SUM(D38:D39) -> -2624.14 | E40: =SUM(E38:E39) -> -2552.01 | F40: =SUM(F38:F39) -> -2750
A42: JÄTEHUOLTO
A43: 6000 | B43: Jätehuolto | C43: -3041.94 | D43: -2873.98 | E43: -2939.55 | F43: -3000
B44: Jätehuolto yhteensä | C44: =SUM(C43) -> -3041.94 | D44: =SUM(D43) -> -2873.98 | E44: =SUM(E43) -> -2939.55 | F44: =SUM(F43) -> -3000
A46: VAHINKOVAKUUTUKSET
A47: 6110 | B47: Kiinteistövakuutus | D47: -1572.16 | E47: -1265.13 | F47: -1255.86
A48: 6115 | B48: Hallinnonturvavakuutus | D48: -160 | E48: -165 | F48: -169
...

Sheet Tulot
A1: Tulot – mistä raha tulee
A2: Lähde: toimintakertomukset ja talousarviovertailut, tilikaudet 2023–2025
A4: Ryhmä | B4: Toteuma 2023 | C4: Budjetti 2023 | D4: Toteuma 2024 | E4: Budjetti 2024 | F4: Toteuma 2025 | G4: Budjetti 2025 | H4: Budjetti 2026 | I4: Muutos 24→25 | J4: Huom.
A5: Hoitovastikkeet | B5: 36237.38 | C5: 35609.69 | D5: 40666.93 | E5: 40252 | F5: 43150.75 | G5: 42187 | H5: 42714.26 | I5: =IFERROR((F5-D5)/D5,"") -> 0.061077145 | J5: as+autokatos+kulutusperust.+kaapeli-tv
A6: Vuokrat (autopaikat) | B6: 720 | C6: 650 | D6: 756 | E6: 756 | F6: 756 | G6: 756 | H6: 756 | I6: =IFERROR((F6-D6)/D6,"") -> 0
A7: Muut tuotot | B7: 250 | C7: 0 | D7: 0 | E7: 0 | F7: 0 | G7: 0 | H7: 0 | I7: =IFERROR((F7-D7)/D7,"") | J7: Esiintyi vain 2023
A8: YHTEENSÄ | B8: =SUM(B5:B7) -> 37207.38 | C8: =SUM(C5:C7) -> 36259.69 | D8: =SUM(D5:D7) -> 41422.93 | E8: =SUM(E5:E7) -> 41008 | F8: =SUM(F5:F7) -> 43906.75 | G8: =SUM(G5:G7) -> 42943 | H8: =SUM(H5:H7) -> 43470.26 | I8: =IFERROR((F8-D8)/D8,"") -> 0.059962441
A11: Hoitovastikkeet tileittäin
A12: Tili | B12: Nimi | C12: Toteuma 2023 | D12: Toteuma 2024 | E12: Toteuma 2025 | F12: Budjetti 2026
A13: 3000 | B13: Hoitovastike, asunnot | D13: 33929.88 | E13: 35642.4 | F13: 35642.04
A14: 3002 | B14: Hoitovastike, autokatokset | D14: 1006.26 | E14: 1056.96 | F14: 1057.12
A15: 3030 | B15: Kulutusperusteinen vastike (vesi) | C15: 3527.5 | D15: 4414.15 | E15: 5119.41 | F15: 4683.12
A16: 3050 | B16: Kaapeli-TV-maksu | D16: 1316.64 | E16: 1331.98 | F16: 1331.98
B17: Hoitovastikkeet yhteensä | C17: =B5 -> 36237.38 | D17: =SUM(D13:D16) -> 40666.93 | E17: =SUM(E13:E16) -> 43150.75 | F17: =SUM(F13:F16) -> 42714.26
A18: 2023: vain kulutusperusteinen vastike (vesi) eritelty tilitasolla lähteessä – as/autokatos/kaapeli-tv olivat 2023-raportissa yhtenä lukuna. Vihreä = linkki yläpuolella olevaan YHTEENSÄ-riviin.
A21: Hoitokate-yhteenveto (tulot - kulut)
A22: Vuosi | B22: Tuotot | C22: Kulut | D22: Hoitokate | E22: Hoitokate-%
A23: Toteuma 2023 | B23: =B8 -> 37207.38 | C23: =ABS(Kulut!D15) -> 34271.63 | D23: =B23-C23 -> 2935.75 | E23: =IFERROR(D23/B23,"") -> 0.078902358
A24: Toteuma 2024 | B24: =D8 -> 41422.93 | C24: =ABS(Kulut!E15) -> 36761.19 | D24: =B24-C24 -> 4661.74 | E24: =IFERROR(D24/B24,"") -> 0.11254008
A25: Toteuma 2025 | B25: =F8 -> 43906.75 | C25: =ABS(Kulut!F15) -> 37911.01 | D25: =B25-C25 -> 5995.74 | E25: =IFERROR(D25/B25,"") -> 0.13655622
A26: Budjetti 2025 | B26: =G8 -> 42943 | C26: =ABS(Kulut!G15) -> 42935.71 | D26: =B26-C26 -> 7.29 | E26: =IFERROR(D26/B26,"") -> 0.00016975991
A27: Budjetti 2026 | B27: =H8 -> 43470.26 | C27: =ABS(Kulut!H15) -> 43470.09 | D27: =B27-C27 -> 0.17 | E27: =IFERROR(D27/B27,"") -> 3.9107197e-06
A29: Vihreä teksti = linkki toiselle välilehdelle tai tämän taulukon omaan summariviin.

Sheet Taloudellinen asema
A1: Taloudellinen asema – tase tiivistettynä
A2: Lähde: tase ja tase-erittelyt 31.12.2024 / 31.12.2025. Esitetty positiivisina euromäärinä (lähdejärjestelmän oma etumerkkikäytäntö on jätetty pois selkeyden vuoksi).
A4: Erä | B4: 31.12.2024 | C4: 31.12.2025 | D4: Muutos
A5: VARAT
A6: Pysyvät vastaavat
A7: Maa- ja vesialueet | B7: 111176 | C7: 111176 | D7: =C7-B7 -> 0
A8: Liittymismaksut | B8: 27553.6 | C8: 27553.6 | D8: =C8-B8 -> 0
A9: Rakennukset (kirjanpitoarvo)* | B9: 1593017.8 | C9: 1592195.8 | D9: =C9-B9 -> -822
A10: Pysyvät vastaavat yhteensä | B10: =SUM(B7:B9) -> 1731747.4 | C10: =SUM(C7:C9) -> 1730925.4 | D10: =C10-B10 -> -822
A12: Vaihtuvat vastaavat
A13: Myyntisaamiset (asukkailta) | B13: 954.76 | C13: 1265.22 | D13: =C13-B13 -> 310.46
A14: Rahat ja pankkisaamiset | B14: 16976.69 | C14: 22208.49 | D14: =C14-B14 -> 5231.8
A15: Vaihtuvat vastaavat yhteensä | B15: =SUM(B13:B14) -> 17931.45 | C15: =SUM(C13:C14) -> 23473.71 | D15: =C15-B15 -> 5542.26
A17: VARAT YHTEENSÄ | B17: =B10+B15 -> 1749678.9 | C17: =C10+C15 -> 1754399.1 | D17: =C17-B17 -> 4720.26
A20: OMA PÄÄOMA JA VELAT
A21: Sidottu oma pääoma
A22: Osakepääoma | B22: 8199 | C22: 8199 | D22: =C22-B22 -> 0
A23: Rakennusrahasto | B23: 1093720.6 | C23: 1093720.6 | D23: =C23-B23 -> 0
A24: Sidottu oma pääoma yhteensä | B24: =SUM(B22:B23) -> 1101919.6 | C24: =SUM(C22:C23) -> 1101919.6 | D24: =C24-B24 -> 0
A26: Vapaa oma pääoma
A27: Muut rahastot (“Lainanlyhennysrahasto”)** | B27: 650000 | C27: 650000 | D27: =C27-B27 -> 0
A28: Kertyneet voittovarat | B28: -4736.16 | C28: 437.58 | D28: =C28-B28 -> 5173.74
A29: Vapaa oma pääoma yhteensä | B29: =SUM(B27:B28) -> 645263.84 | C29: =SUM(C27:C28) -> 650437.58 | D29: =C29-B29 -> 5173.74
A31: OMA PÄÄOMA YHTEENSÄ | B31: =B24+B29 -> 1747183.5 | C31: =C24+C29 -> 1752357.2 | D31: =C31-B31 -> 5173.74
A33: Velat
A34: Muut velat (ennakkomaksut osakkailta) | B34: 761.32 | C34: 645.02 | D34: =C34-B34 -> -116.3
A35: Ostovelat | B35: 1734.07 | C35: 1396.89 | D35: =C35-B35 -> -337.18
A36: Velat yhteensä | B36: =SUM(B34:B35) -> 2495.39 | C36: =SUM(C34:C35) -> 2041.91 | D36: =C36-B36 -> -453.48
A38: OMA PÄÄOMA JA VELAT YHTEENSÄ | B38: =B31+B36 -> 1749678.9 | C38: =C31+C36 -> 1754399.1 | D38: =C38-B38 -> 4720.26
A39: Täsmäytys (Varat – O.P.+Velat, pitää olla 0) | B39: =B17-B38 -> 4.6566129e-10 | C39: =C17-C38 -> 2.3283064e-10
A42: Tunnusluvut | B42: 31.12.2024 | C42: 31.12.2025
A43: Maksuvalmius (vaihtuvat vastaavat / lyh. velat) | B43: =B15/B36 -> 7.1858307 | C43: =C15/C36 -> 11.495957
A44: Kassa kuukausina hoitokuluja | B44: =B14/(ABS(Kulut!E15)/12) -> 5.5417216 | C44: =C14/(ABS(Kulut!F15)/12) -> 7.0296697
A45: Korollinen vieras pääoma | B45: Ei lainaa | C45: Ei lainaa
A47: * Rakennuksen kirjanpitoarvo perustuu verotuksen maksimipoistoihin (n. 0,05 %/v), ei todellista kuntoa tai jäljellä olevaa käyttöikää. Fyysinen elinkaari on Rakennusosat-välilehdellä, ei tässä.
A48: ** Nimestä huolimatta kirjattu vapaaksi omaksi pääomaksi, ei sidotuksi – periaatteessa vapaammin käytettävissä esim. tulevien korjausten rahoitukseen kuin nimi antaa ymmärtää.

Sheet Budjettitarkkuus
A1: Budjettitarkkuus – miten budjetti on osunut
A2: Erotus = Toteuma − Budjetti. Positiivinen = ylitys (kulut: huono; tulot: hyvä), negatiivinen = alitus. Vihreä = linkki Kulut/Tulot-välilehdelle. Arvio 2023 on rekonstruoitu OCR-kuvasta, täsmäytetty Hoitokate-kaavalla senttiin.
A4: KULUT
A5: Ryhmä | B5: Toteuma 2023 | C5: Budjetti 2023 | D5: Erotus 2023 € | E5: Erotus 2023 % | F5: Toteuma 2024 | G5: Budjetti 2024 | H5: Erotus 2024 € | I5: Erotus 2024 % | J5: Toteuma 2025 | K5: Budjetti 2025 | L5: Erotus 2025 € | M5: Erotus 2025 % | N5: Huom.
A6: Henkilöstökulut (hallituspalkkiot) | B6: =Kulut!D5 -> 360 | C6: =Kulut!M5 -> 480 | D6: =B6-C6 -> -120 | E6: =IFERROR(D6/C6,"") -> -0.25 | F6: =Kulut!E5 -> 600 | G6: =Kulut!L5 -> 360 | H6: =F6-G6 -> 240 | I6: =IFERROR(H6/G6,"") -> 0.66666667 | J6: =Kulut!F5 -> 600 | K6: =Kulut!G5 -> 600 | L6: =J6-K6 -> 0 | M6: =IFERROR(L6/K6,"") -> 0 | N6: Pieni euro-määrä, isot %-poikkeamat eivät merkitse paljoa
A7: Hallintopalvelut | B7: =Kulut!D6 -> 8003.7 | C7: =Kulut!M6 -> 7243.96 | D7: =B7-C7 -> 759.74 | E7: =IFERROR(D7/C7,"") -> 0.1048791 | F7: =Kulut!E6 -> 7885.63 | G7: =Kulut!L6 -> 7015 | H7: =F7-G7 -> 870.63 | I7: =IFERROR(H7/G7,"") -> 0.12410976 | J7: =Kulut!F6 -> 7360.76 | K7: =Kulut!G6 -> 7719.32 | L7: =J7-K7 -> -358.56 | M7: =IFERROR(L7/K7,"") -> -0.046449687
A8: Käyttö- ja huoltopalvelut | B8: =Kulut!D7 -> 1975.41 | C8: =Kulut!M7 -> 1916.66 | D8: =B8-C8 -> 58.75 | E8: =IFERROR(D8/C8,"") -> 0.030652281 | F8: =Kulut!E7 -> 1450.42 | G8: =Kulut!L7 -> 1324 | H8: =F8-G8 -> 126.42 | I8: =IFERROR(H8/G8,"") -> 0.095483384 | J8: =Kulut!F7 -> 4624.34 | K8: =Kulut!G7 -> 1332 | L8: =J8-K8 -> 3292.34 | M8: =IFERROR(L8/K8,"") -> 2.4717267 | N8: Ylittää kaikkina kolmena vuotena – budjetti ei huomioi yllätyshuoltokuluja
A9: Ulkoalueiden hoitopalvelut | B9: =Kulut!D8 -> 3784.22 | C9: =Kulut!M8 -> 3300 | D9: =B9-C9 -> 484.22 | E9: =IFERROR(D9/C9,"") -> 0.14673333 | F9: =Kulut!E8 -> 2186.5 | G9: =Kulut!L8 -> 4000 | H9: =F9-G9 -> -1813.5 | I9: =IFERROR(H9/G9,"") -> -0.453375 | J9: =Kulut!F8 -> 2193.69 | K9: =Kulut!G8 -> 4000 | L9: =J9-K9 -> -1806.31 | M9: =IFERROR(L9/K9,"") -> -0.4515775 | N9: Vaihteleva: 2023 ylitti, 2024–2025 alittivat isosti (~-45 %) – ei yksiselitteistä trendiä
A10: Vesi- ja jätevesi | B10: =Kulut!D9 -> 4995.73 | C10: =Kulut!M9 -> 5240 | D10: =B10-C10 -> -244.27 | E10: =IFERROR(D10/C10,"") -> -0.046616412 | F10: =Kulut!E9 -> 6784.9 | G10: =Kulut!L9 -> 5270 | H10: =F10-G10 -> 1514.9 | I10: =IFERROR(H10/G10,"") -> 0.28745731 | J10: =Kulut!F9 -> 7067.26 | K10: =Kulut!G9 -> 7270 | L10: =J10-K10 -> -202.74 | M10: =IFERROR(L10/K10,"") -> -0.027887208
A11: Sähkö | B11: =Kulut!D10 -> 3070.51 | C11: =Kulut!M10 -> 2600 | D11: =B11-C11 -> 470.51 | E11: =IFERROR(D11/C11,"") -> 0.18096538 | F11: =Kulut!E10 -> 2624.14 | G11: =Kulut!L10 -> 2250 | H11: =F11-G11 -> 374.14 | I11: =IFERROR(H11/G11,"") -> 0.16628444 | J11: =Kulut!F10 -> 2552.01 | K11: =Kulut!G10 -> 2860 | L11: =J11-K11 -> -307.99 | M11: =IFERROR(L11/K11,"") -> -0.10768881
A12: Jätehuolto | B12: =Kulut!D11 -> 3041.94 | C12: =Kulut!M11 -> 3300 | D12: =B12-C12 -> -258.06 | E12: =IFERROR(D12/C12,"") -> -0.0782 | F12: =Kulut!E11 -> 2873.98 | G12: =Kulut!L11 -> 3200 | H12: =F12-G12 -> -326.02 | I12: =IFERROR(H12/G12,"") -> -0.10188125 | J12: =Kulut!F11 -> 2939.55 | K12: =Kulut!G11 -> 3000 | L12: =J12-K12 -> -60.45 | M12: =IFERROR(L12/K12,"") -> -0.02015 | N12: Alittaa lievästi joka vuosi – budjetoitu johdonmukaisesti hieman yläkanttiin
A13: Vahinkovakuutukset | B13: =Kulut!D12 -> 2809.46 | C13: =Kulut!M12 -> 2630.11 | D13: =B13-C13 -> 179.35 | E13: =IFERROR(D13/C13,"") -> 0.068191064 | F13: =Kulut!E12 -> 2147.96 | G13: =Kulut!L12 -> 2916 | H13: =F13-G13 -> -768.04 | I13: =IFERROR(H13/G13,"") -> -0.2633882 | J13: =Kulut!F12 -> 1878.41 | K13: =Kulut!G12 -> 1874.39 | L13: =J13-K13 -> 4.02 | M13: =IFERROR(L13/K13,"") -> 0.0021446977
A14: Kiinteistövero | B14: =Kulut!D13 -> 4845.6 | C14: =Kulut!M13 -> 4845.6 | D14: =B14-C14 -> 0 | E14: =IFERROR(D14/C14,"") -> 0 | F14: =Kulut!E13 -> 4859.13 | G14: =Kulut!L13 -> 4859 | H14: =F14-G14 -> 0.13 | I14: =IFERROR(H14/G14,"") -> 2.6754476e-05 | J14: =Kulut!F13 -> 4813.44 | K14: =Kulut!G13 -> 4880 | L14: =J14-K14 -> -66.56 | M14: =IFERROR(L14/K14,"") -> -0.013639344 | N14: Osuu erittäin tarkasti kaikkina kolmena vuotena – täysin ennustettava kuluerä
A15: Korjaukset | B15: =Kulut!D14 -> 1385.06 | C15: =Kulut!M14 -> 3000 | D15: =B15-C15 -> -1614.94 | E15: =IFERROR(D15/C15,"") -> -0.53831333 | F15: =Kulut!E14 -> 5348.53 | G15: =Kulut!L14 -> 8000 | H15: =F15-G15 -> -2651.47 | I15: =IFERROR(H15/G15,"") -> -0.33143375 | J15: =Kulut!F14 -> 3881.55 | K15: =Kulut!G14 -> 9400 | L15: =J15-K15 -> -5518.45 | M15: =IFERROR(L15/K15,"") -> -0.58706915 | N15: Alittaa merkittävästi joka vuosi (keskim. n. -48 %) – selvästi konservatiivinen budjetointi tai korjaukset lykkääntyvät systemaattisesti
A16: YHTEENSÄ | B16: =Kulut!D15 -> 34271.63 | C16: =Kulut!M15 -> 34556.33 | D16: =B16-C16 -> -284.7 | E16: =IFERROR(D16/C16,"") -> -0.0082387221 | F16: =Kulut!E15 -> 36761.19 | G16: =Kulut!L15 -> 39194 | H16: =F16-G16 -> -2432.81 | I16: =IFERROR(H16/G16,"") -> -0.06207098 | J16: =Kulut!F15 -> 37911.01 | K16: =Kulut!G15 -> 42935.71 | L16: =J16-K16 -> -5024.7 | M16: =IFERROR(L16/K16,"") -> -0.11702846
A17: Keskim. itseisarvopoikkeama (kategorioittain) | E17: =SUMPRODUCT(ABS(E6:E15))/10 -> 0.14445509 | I17: =SUMPRODUCT(ABS(I6:I15))/10 -> 0.24901065 | M17: =SUMPRODUCT(ABS(M6:M15))/10 -> 0.37283331
A18: Tarkkuus on heikentynyt vuosi vuodelta (2023: n. 14 %, 2024: n. 25 %) – 2025:n 37 %:a nostaa yksin Käyttö- ja huoltopalveluiden 247 %:n poikkeama (palovaroitinasennus); ilman sitä 2025 olisi osunut selvästi tarkemmin.
A21: TULOT
A22: Ryhmä | B22: Toteuma 2023 | C22: Budjetti 2023 | D22: Erotus 2023 € | E22: Erotus 2023 % | F22: Toteuma 2024 | G22: Budjetti 2024 | H22: Erotus 2024 € | I22: Erotus 2024 % | J22: Toteuma 2025 | K22: Budjetti 2025 | L22: Erotus 2025 € | M22: Erotus 2025 % | N22: Huom.
A23: Hoitovastikkeet | B23: =Tulot!B5 -> 36237.38 | C23: =Tulot!C5 -> 35609.69 | D23: =B23-C23 -> 627.69 | E23: =IFERROR(D23/C23,"") -> 0.017626944 | F23: =Tulot!D5 -> 40666.93 | G23: =Tulot!E5 -> 40252 | H23: =F23-G23 -> 414.93 | I23: =IFERROR(H23/G23,"") -> 0.010308308 | J23: =Tulot!F5 -> 43150.75 | K23: =Tulot!G5 -> 42187 | L23: =J23-K23 -> 963.75 | M23: =IFERROR(L23/K23,"") -> 0.022844715
A24: Vuokrat (autopaikat) | B24: =Tulot!B6 -> 720 | C24: =Tulot!C6 -> 650 | D24: =B24-C24 -> 70 | E24: =IFERROR(D24/C24,"") -> 0.10769231 | F24: =Tulot!D6 -> 756 | G24: =Tulot!E6 -> 756 | H24: =F24-G24 -> 0 | I24: =IFERROR(H24/G24,"") -> 0 | J24: =Tulot!F6 -> 756 | K24: =Tulot!G6 -> 756 | L24: =J24-K24 -> 0 | M24: =IFERROR(L24/K24,"") -> 0
A25: Muut tuotot | B25: =Tulot!B7 -> 250 | C25: =Tulot!C7 -> 0 | D25: =B25-C25 -> 250 | E25: =IFERROR(D25/C25,"") | F25: =Tulot!D7 -> 0 | G25: =Tulot!E7 -> 0 | H25: =F25-G25 -> 0 | I25: =IFERROR(H25/G25,"") | J25: =Tulot!F7 -> 0 | K25: =Tulot!G7 -> 0 | L25: =J25-K25 -> 0 | M25: =IFERROR(L25/K25,"")
A26: YHTEENSÄ | B26: =Tulot!B8 -> 37207.38 | C26: =Tulot!C8 -> 36259.69 | D26: =B26-C26 -> 947.69 | E26: =IFERROR(D26/C26,"") -> 0.026136186 | F26: =Tulot!D8 -> 41422.93 | G26: =Tulot!E8 -> 41008 | H26: =F26-G26 -> 414.93 | I26: =IFERROR(H26/G26,"") -> 0.01011827 | J26: =Tulot!F8 -> 43906.75 | K26: =Tulot!G8 -> 42943 | L26: =J26-K26 -> 963.75 | M26: =IFERROR(L26/K26,"") -> 0.02244254
